<mujoco model="two-joint-limb">
  <compiler angle="radian"/>

  <option gravity="0 9.81 0"/>

  <default>
    <joint damping="0.1"/>
    <geom rgba="1 1 1 0.25"/>
    <general ctrllimited="true" ctrlrange="0 1" dyntype="muscle" dynprm="0.01 0.04 0 0 0 0 0 0 0 0" gaintype="muscle" biastype="muscle" gainprm="0.75 1.05 -1 200 0.5 1.6 1.5 1.3 1.2" biasprm="0.75 1.05 -1 200 0.5 1.6 1.5 1.3 1.2"/>
  </default>

  <worldbody>
    <camera pos="0 -2 0" quat="0.707107 0.707107 0 0"/>
    <light pos="0 1 1" dir="0 -0.707107 -0.707107" diffuse="1 1 1"/>
    <body name="trunk">
      <site name="deltoid1" pos="0.25 0 0" size="0.01"/>
      <site name="latissimus1" pos="-0.25 0 0" size="0.01"/>
      <body name="upper_arm">
        <joint name="shoulder" pos="0 0 0" axis="0 1 0" range="-1.0472 1.0472"/>
        <geom name="humerus" size="0.025 0.2" pos="0 0 -0.2" type="cylinder"/>
        <site name="deltoid2" pos="0.025 0 -0.1" size="0.01"/>
        <site name="latissimus2" pos="-0.025 0 -0.1" size="0.01"/>
        <site name="biceps1" pos="0.05 0 0" size="0.01"/>
        <site name="triceps1" pos="-0.05 0 0" size="0.01"/>
        <body name="lower_arm" pos="0 0 -0.4">
          <joint name="elbow" pos="0 0 0" axis="0 1 0" range="-1.0472 1.0472"/>
          <geom name="radius" size="0.025 0.2875" pos="0.2125 0 0" quat="0.707107 0 -0.707107 0" type="cylinder"/>
          <site name="biceps2" pos="0.1 0 0.03" size="0.01"/>
          <site name="triceps2" pos="-0.08 0 0" size="0.01"/>
          <body name="hand" pos="0.5 0 0">
            <geom name="hand" size="0.05" rgba="1 0.25 0.25 1"/>
          </body>
        </body>
      </body>
    </body>
  </worldbody>

  <tendon>
    <spatial name="deltoid_tendon" limited="true" range="0 1" width="0.005" rgba="1 0 1 1">
      <site site="deltoid1"/>
      <site site="deltoid2"/>
    </spatial>
    <spatial name="latissimus_tendon" limited="true" range="0 1" width="0.005" rgba="1 1 0 1">
      <site site="latissimus1"/>
      <site site="latissimus2"/>
    </spatial>
    <spatial name="biceps_tendon" limited="true" range="0 0.485" width="0.005" rgba="1 0 0 1">
      <site site="biceps1"/>
      <geom geom="humerus"/>
      <site site="biceps2"/>
    </spatial>
    <spatial name="triceps_tendon" limited="true" range="0 0.5" width="0.005" rgba="0 1 0 1">
      <site site="triceps1"/>
      <geom geom="radius"/>
      <site site="triceps2"/>
    </spatial>
  </tendon>

  <actuator>
    <general name="deltoid" tendon="deltoid_tendon" lengthrange="0.153519 0.331943" gainprm="0.75 1.05 100" biasprm="0.75 1.05 100"/>
    <general name="latissimus" tendon="latissimus_tendon" lengthrange="0.153525 0.33195" gainprm="0.75 1.05 100" biasprm="0.75 1.05 100"/>
    <general name="biceps" tendon="biceps_tendon" lengthrange="0.299515 0.472335" gainprm="0.75 1.05 100" biasprm="0.75 1.05 100"/>
    <general name="triceps" tendon="triceps_tendon" lengthrange="0.33086 0.469419" gainprm="0.75 1.05 100" biasprm="0.75 1.05 100"/>
  </actuator>

  <sensor>

    <actuatorpos actuator="deltoid" name="deltoid_length"/>

    <actuatorpos actuator="latissimus" name="latissimus_length"/>

    <actuatorpos actuator="biceps" name="biceps_length"/>

    <actuatorpos actuator="triceps" name="triceps_length"/>

    <actuatorvel actuator="deltoid" name="deltoid_velocity"/>

    <actuatorvel actuator="latissimus" name="latissimus_velocity"/>

    <actuatorvel actuator="biceps" name="biceps_velocity"/>

    <actuatorvel actuator="triceps" name="triceps_velocity"/>
  </sensor>
</mujoco>
