<mujoco model="two-joint-planar-arm">

  <option timestep="0.01" integrator="RK4">
    <flag warmstart="enable" />
  </option>
  
  <visual>
    <map force="0.1" zfar="30" />
    <rgba haze="0 0 0 1" />
    <global offwidth="1920" offheight="1080" elevation="-90" azimuth="90" />
    <quality shadowsize="2048" />
    <headlight ambient="0.3 0.3 0.3" diffuse="0.8 0.8 0.8" specular="0.4 0.4 0.4" />
  </visual>

  <asset>
    <material name="arm_mat" rgba="0.8 0.7 0.6 1" specular="0.1" shininess="0.1" reflectance="0" />
    <material name="tendon_mat" rgba="1 1 1 1" specular="0" shininess="0" reflectance="0"
      emission="0.2" />
  </asset>

  <default>
    <joint stiffness="0" damping="1" />
    <muscle ctrllimited="true" ctrlrange="0 1" vmax="1.2" fpmax="1.4" timeconst=".01 .04" />
    <geom material="arm_mat" />
    <tendon material="tendon_mat" limited="false" width="0.008" />
  </default>

  <worldbody>

    <!-- TRUNK -->
    <body name="trunk" pos="0 0 0">

      <!-- tendon attachment sites -->
      <site name="deltoid_origin" pos=".25 0 0" size="0.01" />
      <site name="latissimus_origin" pos="-0.25 0 0" size="0.01" />

      <!-- UPPER ARM -->
      <body name="upper_arm" pos="0 0 0">

        <!-- shoulder -->
        <joint name="shoulder" type="hinge" axis="0 0 1" range="-60 60" />

        <!-- tendon attachment sites -->
        <site name="deltoid_insert" pos="0.025 -.1 0" size="0.01" />
        <site name="latissimus_insert" pos="-0.025 -.1 0" size="0.01" />
        <site name="biceps_origin" pos="0.05 0 0" size="0.01" />
        <site name="triceps_origin" pos="-0.05 0 0" size="0.01" />

        <!-- humerus -->
        <geom name="humerus" type="cylinder" size="0.025" fromto="0 0 0 0 -.4 0" mass="1.8" />

        <!-- LOWER ARM -->
        <body name="lower_arm" pos="0 -0.4 0">

          <!-- elbow -->
          <joint name="elbow" type="hinge" axis="0 0 1" range="-60 60" />

          <!-- elbow pulley for muscle wrapping -->
          <geom name="elbow_pulley"
            type="cylinder"
            size="0.025 0.025"
            pos="0 0 0" />


          <!-- tendon attachment sites -->
          <site name="biceps_insert" pos=".1 .03 0" size="0.01" />
          <site name="triceps_insert" pos="-.08 0 0" size="0.01" />

          <!-- radius -->
          <geom name="radius" type="cylinder" size="0.025" fromto="-.075 0 0 .5 0 0" mass="1.2" />

          <!-- HAND -->
          <body name="hand" pos="0.5 0 0">
            <geom name="hand" type="sphere" size="0.05" pos="0 0 0" rgba="1 .25 .25 1" mass="0.4" />
          </body>
        </body>
      </body>
    </body>

    <!-- TARGET -->
    <body name="target" mocap="true" pos="0 0 0">
      <geom name="target" size=".025" type="sphere" contype="0" conaffinity="0"
        rgba="0 .75 1 1" />
    </body>
  </worldbody>

  <tendon>
    <spatial name="deltoid_tendon" rgba="1 0 1 1">
      <site site="deltoid_origin" />
      <site site="deltoid_insert" />
    </spatial>
    <spatial name="latissimus_tendon" rgba="1 1 0 1">
      <site site="latissimus_origin" />
      <site site="latissimus_insert" />
    </spatial>
    <spatial name="biceps_tendon" rgba="1 0 0 1">
      <site site="biceps_origin" />
      <geom geom="elbow_pulley" />
      <site site="biceps_insert" />
    </spatial>
    <spatial name="triceps_tendon" rgba="0 1 0 1">
      <site site="triceps_origin" />
      <geom geom="radius" />
      <site site="triceps_insert" />
    </spatial>
  </tendon>

  <actuator>
    <muscle name="deltoid" tendon="deltoid_tendon" force="100" />
    <muscle name="latissimus" tendon="latissimus_tendon" force="100" />
    <muscle name="biceps" tendon="biceps_tendon" force="100" />
    <muscle name="triceps" tendon="triceps_tendon" force="100" />
  </actuator>

  <sensor>
    <actuatorpos name="deltoid_length" actuator="deltoid" />
    <actuatorpos name="latissimus_length" actuator="latissimus" />
    <actuatorpos name="biceps_length" actuator="biceps" />
    <actuatorpos name="triceps_length" actuator="triceps" />
    <actuatorvel name="deltoid_velocity" actuator="deltoid" />
    <actuatorvel name="latissimus_velocity" actuator="latissimus" />
    <actuatorvel name="biceps_velocity" actuator="biceps" />
    <actuatorvel name="triceps_velocity" actuator="triceps" />
    <actuatorfrc name="deltoid_force" actuator="deltoid" />
    <actuatorfrc name="latissimus_force" actuator="latissimus" />
    <actuatorfrc name="biceps_force" actuator="biceps" />
    <actuatorfrc name="triceps_force" actuator="triceps" />
  </sensor>

</mujoco>