<mujoco model="two-joint-limb">

  <visual>
    <map force="0.1" zfar="30" />
    <rgba haze="0 0 0 1" />
    <global offwidth="1920" offheight="1080" elevation="-90" azimuth="0" />
    <quality shadowsize="2048" />
    <headlight ambient="0.3 0.3 0.3" diffuse="0.8 0.8 0.8" specular="0.4 0.4 0.4"/>
  </visual>

  <asset>
    <!-- No skybox, no grid -->
    <material name="arm_mat" rgba="0.8 0.7 0.6 1" specular="0.1" shininess="0.1" reflectance="0"/>
    <material name="tendon_mat" rgba="1 1 1 1" specular="0" shininess="0" reflectance="0" emission="0.2"/>
  </asset>

  <default>
    <joint damping="0.1" />
    <muscle ctrllimited="true" ctrlrange="0 1" />
    <geom material="arm_mat" />
    <tendon material="tendon_mat" />
  </default>

  <worldbody>
    <!-- No extra lights, just headlight for soft shading -->
    <camera name="top" mode="fixed" pos="0 0 3.5" euler="0 0 0" fovy="30"/>
    <!-- No floor, so background is black -->

    <!-- TRUNK -->
    <body name="trunk" pos="0 0 0">

      <!-- tendon attachment sites -->
      <site name="deltoid1" pos=".25 0 0" size="0.01" />
      <site name="latissimus1" pos="-0.25 0 0" size="0.01" />

      <!-- UPPER ARM -->
      <body name="upper_arm" pos="0 0 0">

        <!-- shoulder -->
        <joint name="shoulder" type="hinge" axis="0 0 1" range="-60 60" />

        <!-- tendon attachment sites -->
        <site name="deltoid2" pos="0.025 -.1 0" size="0.01" />
        <site name="latissimus2" pos="-0.025 -.1 0" size="0.01" />
        <site name="biceps1" pos="0.05 0 0" size="0.01" />
        <site name="triceps1" pos="-0.05 0 0" size="0.01" />

        <!-- humerus -->
        <geom name="humerus" type="cylinder" size="0.025" fromto="0 0 0 0 -.4 0" />

        <!-- LOWER ARM -->
        <body name="lower_arm" pos="0 -0.4 0">

          <!-- elbow -->
          <joint name="elbow" type="hinge" axis="0 0 1" range="-60 60" />

          <!-- tendon attachment sites -->
          <site name="biceps2" pos=".1 .03 0" size="0.01" />
          <site name="triceps2" pos="-.08 0 0" size="0.01" />

          <!-- radius -->
          <geom name="radius" type="cylinder" size="0.025" fromto="-.075 0 0 .5 0 0" />

          <!-- HAND -->
          <body name="hand" pos="0.5 0 0">
            <geom name="hand" type="sphere" size="0.05" pos="0 0 0" rgba="1 .25 .25 1" />
            <site name="nail2" pos="0 0 0" />
          </body>
        </body>
      </body>
    </body>

    <!-- TARGET -->
    <body name="target" mocap="true" pos="0 0 0">
      <geom name="target" size=".025" type="sphere" contype="0" conaffinity="0"
        rgba="0 .75 1 1" />
    </body>

    <!-- NAIL -->
    <body name="nail" mocap="true" pos="0 0 0">
      <geom name="nail" type="cylinder" size=".005" fromto="0 0 -.1 0 0 .1" contype="0"
        conaffinity="0" rgba="1 1 1 1" />
      <site name="nail1" pos="0 0 0" />
    </body>
  </worldbody>

  <equality>
    <connect name="nail_eq" active="false" site1="nail1" site2="nail2" />
  </equality>

  <tendon>
    <spatial name="deltoid_tendon" limited="true" range="0 1" width="0.008" rgba="1 0 1 1">
      <site site="deltoid1" />
      <site site="deltoid2" />
    </spatial>

    <spatial name="latissimus_tendon" limited="true" range="0 1" width="0.008" rgba="1 1 0 1">
      <site site="latissimus1" />
      <site site="latissimus2" />
    </spatial>

    <spatial name="biceps_tendon" limited="true" range="0 .485" width="0.008" rgba="1 0 0 1">
      <site site="biceps1" />
      <geom geom="humerus" />
      <site site="biceps2" />
    </spatial>

    <spatial name="triceps_tendon" limited="true" range="0 .5" width="0.008" rgba="0 1 0 1">
      <site site="triceps1" />
      <geom geom="radius" />
      <site site="triceps2" />
    </spatial>
  </tendon>

  <actuator>
    <muscle name="deltoid" tendon="deltoid_tendon" ctrlrange="0 1" force="100" timeconst=".01 .04" />
    <muscle name="latissimus" tendon="latissimus_tendon" ctrlrange="0 1" force="100"
      timeconst=".01 .04" />
    <muscle name="biceps" tendon="biceps_tendon" ctrlrange="0 1" force="100" timeconst=".01 .04" />
    <muscle name="triceps" tendon="triceps_tendon" ctrlrange="0 1" force="100" timeconst=".01 .04" />
  </actuator>

  <sensor>
    <actuatorpos name="deltoid_length" actuator="deltoid" />
    <actuatorpos name="latissimus_length" actuator="latissimus" />
    <actuatorpos name="biceps_length" actuator="biceps" />
    <actuatorpos name="triceps_length" actuator="triceps" />
    <actuatorvel name="deltoid_velocity" actuator="deltoid" />
    <actuatorvel name="latissimus_velocity" actuator="latissimus" />
    <actuatorvel name="biceps_velocity" actuator="biceps" />
    <actuatorvel name="triceps_velocity" actuator="triceps" />
    <actuatorfrc name="deltoid_force" actuator="deltoid" />
    <actuatorfrc name="latissimus_force" actuator="latissimus" />
    <actuatorfrc name="biceps_force" actuator="biceps" />
    <actuatorfrc name="triceps_force" actuator="triceps" />
  </sensor>

</mujoco>