<mujoco model="two-joint-limb">

  <default>
    <joint damping="0.1"/>
    <geom rgba="1 1 1 .25"/>
    <muscle ctrllimited="true" ctrlrange="0 1"/>
  </default>

  <worldbody>

    <camera pos="0 -2 0" xyaxes="1 0 0 0 0 1"/>
    <light pos="0 1 1" dir="0 -1 -1" diffuse="1 1 1"/>

    <!-- TRUNK -->
    <body name="trunk" pos="0 0 0">

      <!-- <joint name="bah" type="hinge" axis="0 1 0"/> -->

      <!-- tendon attachment sites -->
      <site name="flexor1" pos=".25 0 0" size="0.01"/>
      <site name="extensor1" pos="-0.25 0 0" size="0.01"/>
      
       <!-- scapula -->
      <!-- <geom name="scapula" type="sphere" size="0.05"/> -->

      <!-- UPPER ARM -->
      <body name="upper_arm" pos="0 0 0">

        <!-- shoulder -->
        <joint name="shoulder" type="hinge" axis="0 1 0" range = "-60 60"/>

        <!-- tendon attachment sites -->
        <site name="flexor2" pos="0.025 0 -.1" size="0.01"/>
        <site name="extensor2" pos="-0.025 0 -.1" size="0.01"/>
        <site name="biceps1" pos="0.05 0 0" size="0.01"/>
        <site name="triceps1" pos="-0.05 0 0" size="0.01"/>

        <!-- humerus -->
        <!-- <geom name="humerus_head" type="sphere" size="0.05" pos="0 0 0" euler="90 0 90"/> -->
        <geom name="humerus" type="cylinder" size="0.025" fromto="0 0 0  0 0 -.4"/>
        <!-- <geom name="humerus_collider" type="cylinder" size="0.025" fromto="0 0 0  0 0 -.4"/> -->

        <!-- LOWER ARM -->
        <body name="lower_arm" pos="0 0 -0.4">

          <!-- elbow -->
          <joint name="elbow" type="hinge" axis="0 1 0" range = "-60 60"/>

          <!-- tendon attachment sites -->
          <site name="biceps2" pos="0.1 0 .03" size="0.01"/>
          <!-- <site name="triceps_wrap" pos="-.2 0 -.1"/> -->
          <site name="triceps2" pos="-.08 0 0" size="0.01"/>

          <!-- radius -->
          <!-- <geom name="radius_head" type="sphere" size="0.03" pos="-.1 0 0" euler="90 0 90" /> -->
          <geom name="radius" type="cylinder" size="0.025" fromto="-.075 0 0 .5 0 0"/>

          <!-- HAND -->
          <body name="hand" pos="0.5 0 0">
            <geom name="hand" type="sphere" size="0.05" pos="0 0 0" rgba="1 .25 .25 1"/>
          </body>
        </body>
      </body>
    </body>

    <body pos="0.3 0 -.3">
      <!-- <joint type="free"/> -->
      <geom size="0.07 0.1" type="cylinder"/>
    </body>
  </worldbody>
  
  <tendon>
    <spatial name="flexor" limited="true" range="0 1" width="0.005" rgba="1 0 1 1">
      <site site="flexor1"/>
      <site site="flexor2"/>
    </spatial>

    <spatial name="extensor" limited="true" range="0 1" width="0.005" rgba="1 1 0 1">
      <site site="extensor1"/>
      <site site="extensor2"/>
    </spatial>

    <spatial name="biceps" limited="true" range="0 .485" width="0.005" rgba="1 0 0 1">
      <site site="biceps1"/>
      <geom geom="humerus"/>
      <site site="biceps2"/>
    </spatial>

    <spatial name="triceps" limited="true" range="0 .5" width="0.005" rgba="0 1 0 1">
      <site site="triceps1"/>
      <geom geom="radius"/>
      <!-- <geom geom="radius_head" sidesite="triceps_wrap"></geom> -->
      <site site="triceps2"/>
    </spatial>
  </tendon>

  <actuator>
    <muscle name="flexor_muscle" tendon="flexor" ctrlrange="0 1" force="100"/>
    <muscle name="extensor_muscle" tendon="extensor" ctrlrange="0 1" force="100"/>
    <muscle name="biceps_muscle" tendon="biceps" ctrlrange="0 1" force="100"/>
    <muscle name="triceps_muscle" tendon="triceps" ctrlrange="0 1" force="100"/>
  </actuator>

  <sensor>
    <tendonpos name="flexor_length" tendon="flexor"/>
    <tendonvel name="flexor_velocity" tendon="flexor"/>
    <tendonpos name="extensor_length" tendon="extensor"/>
    <tendonvel name="extensor_velocity" tendon="extensor"/>
    <tendonpos name="biceps_length" tendon="biceps"/>
    <tendonvel name="biceps_velocity" tendon="biceps"/>
    <tendonpos name="triceps_length" tendon="triceps"/>
    <tendonvel name="triceps_velocity" tendon="triceps"/>
    <!-- <force name="biceps_force" tendon="biceps"/>
    <force name="triceps_force" tendon="triceps"/> -->
  </sensor>

</mujoco>