<mujoco model="two-joint-limb">
  <option gravity="0 9.81 0"/>
  
  <default>  
    <joint damping="0.1"/>
    <geom rgba="1 1 1 .25"/>
    <muscle ctrllimited="true" ctrlrange="0 1"/>
  </default>

  <worldbody>

    <light pos="0 1 1" dir="0 -1 -1" diffuse="1 1 1"/>

    <!-- TRUNK -->
    <body name="trunk" pos="0 0 0">

      <!-- <joint name="bah" type="hinge" axis="0 1 0"/> -->

      <!-- tendon attachment sites -->
      <site name="deltoid1" pos=".25 0 0" size="0.01"/>
      <site name="latissimus1" pos="-0.25 0 0" size="0.01"/>
      
       <!-- scapula -->
      <!-- <geom name="scapula" type="sphere" size="0.05"/> -->

      <!-- UPPER ARM -->
      <body name="upper_arm" pos="0 0 0">

        <!-- shoulder -->
        <joint name="shoulder" type="hinge" axis="0 1 0" range = "-60 60"/>

        <!-- tendon attachment sites -->
        <site name="deltoid2" pos="0.025 0 -.1" size="0.01"/>
        <site name="latissimus2" pos="-0.025 0 -.1" size="0.01"/>
        <site name="biceps1" pos="0.05 0 0" size="0.01"/>
        <site name="triceps1" pos="-0.05 0 0" size="0.01"/>

        <!-- humerus -->
        <!-- <geom name="humerus_head" type="sphere" size="0.05" pos="0 0 0" euler="90 0 90"/> -->
        <geom name="humerus" type="cylinder" size="0.025" fromto="0 0 0  0 0 -.4"/>
        <!-- <geom name="humerus_collider" type="cylinder" size="0.025" fromto="0 0 0  0 0 -.4"/> -->

        <!-- LOWER ARM -->
        <body name="lower_arm" pos="0 0 -0.4">

          <!-- elbow -->
          <joint name="elbow" type="hinge" axis="0 1 0" range = "-60 60"/>
          <!-- <joint name="elbow" type="ball"/> -->

          <!-- tendon attachment sites -->
          <site name="biceps2" pos="0.1 0 .03" size="0.01"/>
          <!-- <site name="triceps_wrap" pos="-.2 0 -.1"/> -->
          <site name="triceps2" pos="-.08 0 0" size="0.01"/>

          <!-- radius -->
          <!-- <geom name="radius_head" type="sphere" size="0.03" pos="-.1 0 0" euler="90 0 90" /> -->
          <geom name="radius" type="cylinder" size="0.025" fromto="-.075 0 0 .5 0 0"/>

          <!-- HAND -->
          <body name="hand" pos="0.5 0 0">
            <geom name="hand" type="sphere" size="0.05" pos="0 0 0" rgba="1 .25 .25 1"/>
          </body>
        </body>
      </body>
    </body>

    <body name="target" mocap="true" pos="0 0 0">
      <!-- <joint type="free"/> -->
      <geom name = "target" size=".025" type="sphere" contype="0" conaffinity="0" group="1" rgba="0 .75 1 1"/>
    </body>
  </worldbody>
  
  <tendon>
    <spatial name="deltoid_tendon" limited="true" range="0 1" width="0.005" rgba="1 0 1 1">
      <site site="deltoid1"/>
      <site site="deltoid2"/>
    </spatial>

    <spatial name="latissimus_tendon" limited="true" range="0 1" width="0.005" rgba="1 1 0 1">
      <site site="latissimus1"/>
      <site site="latissimus2"/>
    </spatial>

    <spatial name="biceps_tendon" limited="true" range="0 .485" width="0.005" rgba="1 0 0 1">
      <site site="biceps1"/>
      <geom geom="humerus"/>
      <site site="biceps2"/>
    </spatial>

    <spatial name="triceps_tendon" limited="true" range="0 .5" width="0.005" rgba="0 1 0 1">
      <site site="triceps1"/>
      <geom geom="radius"/>
      <!-- <geom geom="radius_head" sidesite="triceps_wrap"></geom> -->
      <site site="triceps2"/>
    </spatial>
  </tendon>

  <actuator>
    <muscle name="deltoid" tendon="deltoid_tendon" ctrlrange="0 1" force="100"/>
    <muscle name="latissimus" tendon="latissimus_tendon" ctrlrange="0 1" force="100"/>
    <muscle name="biceps" tendon="biceps_tendon" ctrlrange="0 1" force="100"/>
    <muscle name="triceps" tendon="triceps_tendon" ctrlrange="0 1" force="100"/>
  </actuator>

  <sensor>
    <actuatorpos name="deltoid_length" actuator="deltoid"/>
    <actuatorpos name="latissimus_length" actuator="latissimus"/>
    <actuatorpos name="biceps_length" actuator="biceps"/>
    <actuatorpos name="triceps_length" actuator="triceps"/>
    <actuatorvel name="deltoid_velocity" actuator="deltoid"/>
    <actuatorvel name="latissimus_velocity" actuator="latissimus"/>
    <actuatorvel name="biceps_velocity" actuator="biceps"/>
    <actuatorvel name="triceps_velocity" actuator="triceps"/>
    <actuatorfrc name="deltoid_force" actuator="deltoid"/>
    <actuatorfrc name="latissimus_force" actuator="latissimus"/>
    <actuatorfrc name="biceps_force" actuator="biceps"/>
    <actuatorfrc name="triceps_force" actuator="triceps"/>
  </sensor>

</mujoco>